# Promise，async/await

## 回调

## 处理 Error

1. callback 的第一个参数是为 error 而保留的。一旦出现 error，callback(err) 就会被调用。
2. 第二个参数（和下一个参数，如果需要的话）用于成功的结果。此时 callback(null, result1, result2…) 就会被调用。

## Promise

```js
let promise = new Promise(function(resolve, reject) {
  // executor (生产者代码)
});
```

* resolve(value) —— 如果任务成功完成并带有结果 value。
* reject(error) —— 如果出现了 error，error 即为 error 对象。

executor 会自动运行并尝试执行一项工作。尝试结束后，如果成功则调用 resolve，如果出现 error 则调用 reject。

由 new Promise 构造器返回的 promise 对象具有以下内部属性：

* state --最初是 pending 然后 resolve被调用时变为 fulfilled，或者在 reject 被调用时变为 rejected。
* result -- 最初是 undefined， 然后resolve(value) 被调用时变为 value， 或者在reject(error) 被调用时变为error。

executor 只能调用一个 resolve 或一个 reject。任何状态的更改都是最终的。
并且，resolve/reject 只需要一个参数（或不包含任何参数），并且将忽略额外的参数。

如果什么东西出了问题， executor 应该调用 reject。建议使用 Error 对象（或继承自 Error 的对象）。这样做的理由很快就会显而易见。

state 和 result 都是内部的

Promise 对象的 state 和 result 属性都是内部的。我们无法直接访问它们。

### 消费者：then，catch，finally

.then

.then 的第一个参数是一个函数，该函数将在 promise resolved 后运行并接收结果。

.then 的第二个参数也是一个函数，该函数将在 promise rejected 后运行并接收 error。

只对成功完成的情况感兴趣，那么我们可以只为 .then 提供一个函数参数。

catch

只对 error 感兴趣，那么我们可以使用 null 作为第一个参数：.then(null, errorHandlingFunction)。或者我们也可以使用 .catch(errorHandlingFunction)。

finally

f 总是在 promise 被 settled 时运行：即 promise 被 resolve 或 reject。

finally 是执行清理（cleanup）的很好的处理程序（handler），例如无论结果如何，都停止使用不再需要的加载指示符（indicator）。

finally(f) 与 then(f,f) 一些细微的区别：

1. finally 处理程序没有参数。在finally中，不知道promise成功与否。
2. finally 处理程序将结果和error传递给下一个处理程序。